I'm sorry, but an uncaught exception occurred.

While running game code:
WindowsError: [Error 32] The process cannot access the file because it is being used by another process

-- Full Traceback ------------------------------------------------------------

Full traceback:
  File "C:\Users\Patrick\renpy-6.99.3-sdk\renpy\bootstrap.py", line 288, in bootstrap
    renpy.main.main()
  File "C:\Users\Patrick\renpy-6.99.3-sdk\renpy\main.py", line 431, in main
    renpy.persistent.update(True)
  File "C:\Users\Patrick\renpy-6.99.3-sdk\renpy\persistent.py", line 359, in update
    save()
  File "C:\Users\Patrick\renpy-6.99.3-sdk\renpy\persistent.py", line 369, in save
    renpy.loadsave.location.save_persistent(data)
  File "C:\Users\Patrick\renpy-6.99.3-sdk\renpy\savelocation.py", line 464, in save_persistent
    l.save_persistent(data)
  File "C:\Users\Patrick\renpy-6.99.3-sdk\renpy\savelocation.py", line 332, in save_persistent
    safe_rename(fn_new, fn)
  File "C:\Users\Patrick\renpy-6.99.3-sdk\renpy\loadsave.py", line 193, in safe_rename
    os.rename(old, new)
WindowsError: [Error 32] The process cannot access the file because it is being used by another process

Windows-8-6.2.9200
Ren'Py 6.99.4.467
raindrops 0.0
